Workbook

Sheet Spread Monitor
A1: Bond spread variation since 14.07.2026
A2: Anchor date | B2: 46217 | C2: Blue on yellow = the only cell to edit. Everything else is a formula.
A3: Bonds priced | B3: =COUNT($S$7:$S$850)&" of "&COUNTA($A$7:$A$850) | C3: Paste additional ISINs at the bottom of column A - formulas already run to row 850.
A4: Data | B4: Bloomberg BDP (add-in must be connected). Press F9 / Ctrl+Alt+F9 to refresh.
A6: ISIN | B6: Company | C6: Company description | D6: SYZ view | E6: Sector | F6: Country | G6: Ccy | H6: Rating | I6: Classification | J6: Structure | K6: Coupon | L6: Maturity | M6: Den. (k) | N6: Price | O6: YTW (%) | P6: Mod. dur. | Q6: Spread today (bp) | R6: ="Spread on "&TEXT($B$2,"dd.mm.yyyy")&" (bp)" | S6: ="Spread change since "&TEXT($B$2,"dd.mm.yyyy")&" (bp)" | T6: ="YTW on "&TEXT($B$2,"dd.mm.yyyy")&" (%)" | U6: ="YTW change since "&TEXT($B$2,"dd.mm.yyyy")&" (%)" | V6: Rank widening | W6: Rank tightening | X6: Key widening | Y6: Key tightening
A7: USN15516AB83 | B7: =IF($A7="","",PROPER(_xll.BDP($A7&" Corp","NAME"))) | C7: =IF($A7="","",IFERROR(INDEX(Company_desc!$B$2:$B$1144,MATCH($A7,Company_desc!$A$2:$A$1144,0)),IFERROR(INDEX(SYZ_static!$Q$2:$Q$806,MATCH($A7,SYZ_static!$A$2:$A$806,0)),""))) | D7: =IF($A7="","",IFERROR(INDEX(SYZ_static!$B$2:$B$806,MATCH($A7,SYZ_static!$A$2:$A$806,0)),"")) | E7: =IF($A7="","",_xll.BDP($A7&" Corp","INDUSTRY_SECTOR")) | F7: =IF($A7="","",PROPER(_xll.BDP($A7&" Corp","COUNTRY_FULL_NAME"))) | G7: =IF($A7="","",_xll.BDP($A7&" Corp","CRNCY")) | H7: =IF($A7="","",IFERROR(INDEX(SYZ_static!$T$2:$T$806,MATCH($A7,SYZ_static!$A$2:$A$806,0)),_xll.BDP($A7&" Corp","RTG_SP"))) | I7: =IF($A7="","",IFERROR(INDEX(SYZ_static!$S$2:$S$806,MATCH($A7,SYZ_static!$A$2:$A$806,0)),"")) | J7: =IF($A7="","",_xll.BDP($A7&" Corp","PAYMENT_RANK")) | K7: =IF($A7="","",_xll.BDP($A7&" Corp","CPN")) | L7: =IF($A7="","",_xll.BDP($A7&" Corp","MATURITY")) | M7: =IF($A7="","",IFERROR(_xll.BDP($A7&" Corp","MIN_PIECE")/1000,"")) | N7: =IF($A7="","",_xll.BDP($A7&" Corp","PX_LAST")) | O7: =IF($A7="","",_xll.BDP($A7&" Corp","YAS_BOND_YLD","YAS_YLD_FLAG=15")) | P7: =IF($A7="","",_xll.BDP($A7&" Corp","YAS_MOD_DUR")) | Q7: =IF($A7="","",_xll.BDP($A7&" Corp","YAS_OAS_SPRD")) | R7: =IF($A7="","",_xll.BDP($A7&" Corp","YAS_OAS_SPRD","SETTLE_DT",$B$2)) | S7: =IF($A7="","",IF(OR(NOT(ISNUMBER($Q7)),NOT(ISNUMBER($R7))),"",$Q7-$R7)) | T7: =IF($A7="","",_xll.BDP($A7&" Corp","YAS_BOND_YLD","YAS_YLD_FLAG=15","SETTLE_DT",$B$2)) | U7: =IF($A7="","",IF(OR(NOT(ISNUMBER($O7)),NOT(ISNUMBER($T7))),"",$O7-$T7)) | V7: =IF(NOT(ISNUMBER($S7)),"",COUNTIFS($G$7:$G$850,$G7,$S$7:$S$850,">"&$S7)+COUNTIFS($G$7:$G7,$G7,$S$7:$S7,$S7)) | W7: =IF(NOT(ISNUMBER($S7)),"",COUNTIFS($G$7:$G$850,$G7,$S$7:$S$850,"<"&$S7)+COUNTIFS($G$7:$G7,$G7,$S$7:$S7,$S7)) | X7: =IF($V7="","",$G7&"|"&$V7) | Y7: =IF($W7="","",$G7&"|"&$W7)
A8: USN15516AG70 | B8: =IF($A8="","",PROPER(_xll.BDP($A8&" Corp","NAME"))) | C8: =IF($A8="","",IFERROR(INDEX(Company_desc!$B$2:$B$1144,MATCH($A8,Company_desc!$A$2:$A$1144,0)),IFERROR(INDEX(SYZ_static!$Q$2:$Q$806,MATCH($A8,SYZ_static!$A$2:$A$806,0)),""))) | D8: =IF($A8="","",IFERROR(INDEX(SYZ_static!$B$2:$B$806,MATCH($A8,SYZ_static!$A$2:$A$806,0)),"")) | E8: =IF($A8="","",_xll.BDP($A8&" Corp","INDUSTRY_SECTOR")) | F8: =IF($A8="","",PROPER(_xll.BDP($A8&" Corp","COUNTRY_FULL_NAME"))) | G8: =IF($A8="","",_xll.BDP($A8&" Corp","CRNCY")) | H8: =IF($A8="","",IFERROR(INDEX(SYZ_static!$T$2:$T$806,MATCH($A8,SYZ_static!$A$2:$A$806,0)),_xll.BDP($A8&" Corp","RTG_SP"))) | I8: =IF($A8="","",IFERROR(INDEX(SYZ_static!$S$2:$S$806,MATCH($A8,SYZ_static!$A$2:$A$806,0)),"")) | J8: =IF($A8="","",_xll.BDP($A8&" Corp","PAYMENT_RANK")) | K8: =IF($A8="","",_xll.BDP($A8&" Corp","CPN")) | L8: =IF($A8="","",_xll.BDP($A8&" Corp","MATURITY")) | M8: =IF($A8="","",IFERROR(_xll.BDP($A8&" Corp","MIN_PIECE")/1000,"")) | N8: =IF($A8="","",_xll.BDP($A8&" Corp","PX_LAST")) | O8: =IF($A8="","",_xll.BDP($A8&" Corp","YAS_BOND_YLD","YAS_YLD_FLAG=15")) | P8: =IF($A8="","",_xll.BDP($A8&" Corp","YAS_MOD_DUR")) | Q8: =IF($A8="","",_xll.BDP($A8&" Corp","YAS_OAS_SPRD")) | R8: =IF($A8="","",_xll.BDP($A8&" Corp","YAS_OAS_SPRD","SETTLE_DT",$B$2)) | S8: =IF($A8="","",IF(OR(NOT(ISNUMBER($Q8)),NOT(ISNUMBER($R8))),"",$Q8-$R8)) | T8: =IF($A8="","",_xll.BDP($A8&" Corp","YAS_BOND_YLD","YAS_YLD_FLAG=15","SETTLE_DT",$B$2)) | U8: =IF($A8="","",IF(OR(NOT(ISNUMBER($O8)),NOT(ISNUMBER($T8))),"",$O8-$T8)) | V8: =IF(NOT(ISNUMBER($S8)),"",COUNTIFS($G$7:$G$850,$G8,$S$7:$S$850,">"&$S8)+COUNTIFS($G$7:$G8,$G8,$S$7:$S8,$S8)) | W8: =IF(NOT(ISNUMBER($S8)),"",COUNTIFS($G$7:$G$850,$G8,$S$7:$S$850,"<"&$S8)+COUNTIFS($G$7:$G8,$G8,$S$7:$S8,$S8)) | X8: =IF($V8="","",$G8&"|"&$V8) | Y8: =IF($W8="","",$G8&"|"&$W8)
A9: USU60050AA61 | B9: =IF($A9="","",PROPER(_xll.BDP($A9&" Corp","NAME"))) | C9: =IF($A9="","",IFERROR(INDEX(Company_desc!$B$2:$B$1144,MATCH($A9,Company_desc!$A$2:$A$1144,0)),IFERROR(INDEX(SYZ_static!$Q$2:$Q$806,MATCH($A9,SYZ_static!$A$2:$A$806,0)),""))) | D9: =IF($A9="","",IFERROR(INDEX(SYZ_static!$B$2:$B$806,MATCH($A9,SYZ_static!$A$2:$A$806,0)),"")) | E9: =IF($A9="","",_xll.BDP($A9&" Corp","INDUSTRY_SECTOR")) | F9: =IF($A9="","",PROPER(_xll.BDP($A9&" Corp","COUNTRY_FULL_NAME"))) | G9: =IF($A9="","",_xll.BDP($A9&" Corp","CRNCY")) | H9: =IF($A9="","",IFERROR(INDEX(SYZ_static!$T$2:$T$806,MATCH($A9,SYZ_static!$A$2:$A$806,0)),_xll.BDP($A9&" Corp","RTG_SP"))) | I9: =IF($A9="","",IFERROR(INDEX(SYZ_static!$S$2:$S$806,MATCH($A9,SYZ_static!$A$2:$A$806,0)),"")) | J9: =IF($A9="","",_xll.BDP($A9&" Corp","PAYMENT_RANK")) | K9: =IF($A9="","",_xll.BDP($A9&" Corp","CPN")) | L9: =IF($A9="","",_xll.BDP($A9&" Corp","MATURITY")) | M9: =IF($A9="","",IFERROR(_xll.BDP($A9&" Corp","MIN_PIECE")/1000,"")) | N9: =IF($A9="","",_xll.BDP($A9&" Corp","PX_LAST")) | O9: =IF($A9="","",_xll.BDP($A9&" Corp","YAS_BOND_YLD","YAS_YLD_FLAG=15")) | P9: =IF($A9="","",_xll.BDP($A9&" Corp","YAS_MOD_DUR")) | Q9: =IF($A9="","",_xll.BDP($A9&" Corp","YAS_OAS_SPRD")) | R9: =IF($A9="","",_xll.BDP($A9&" Corp","YAS_OAS_SPRD","SETTLE_DT",$B$2)) | S9: =IF($A9="","",IF(OR(NOT(ISNUMBER($Q9)),NOT(ISNUMBER($R9))),"",$Q9-$R9)) | T9: =IF($A9="","",_xll.BDP($A9&" Corp","YAS_BOND_YLD","YAS_YLD_FLAG=15","SETTLE_DT",$B$2)) | U9: =IF($A9="","",IF(OR(NOT(ISNUMBER($O9)),NOT(ISNUMBER($T9))),"",$O9-$T9)) | V9: =IF(NOT(ISNUMBER($S9)),"",COUNTIFS($G$7:$G$850,$G9,$S$7:$S$850,">"&$S9)+COUNTIFS($G$7:$G9,$G9,$S$7:$S9,$S9)) | W9: =IF(NOT(ISNUMBER($S9)),"",COUNTIFS($G$7:$G$850,$G9,$S$7:$S$850,"<"&$S9)+COUNTIFS($G$7:$G9,$G9,$S$7:$S9,$S9)) | X9: =IF($V9="","",$G9&"|"&$V9) | Y9: =IF($W9="","",$G9&"|"&$W9)
A10: USU1065PAA94 | B10: =IF($A10="","",PROPER(_xll.BDP($A10&" Corp","NAME"))) | C10: =IF($A10="","",IFERROR(INDEX(Company_desc!$B$2:$B$1144,MATCH($A10,Company_desc!$A$2:$A$1144,0)),IFERROR(INDEX(SYZ_static!$Q$2:$Q$806,MATCH($A10,SYZ_static!$A$2:$A$806,0)),""))) | D10: =IF($A10="","",IFERROR(INDEX(SYZ_static!$B$2:$B$806,MATCH($A10,SYZ_static!$A$2:$A$806,0)),"")) | E10: =IF($A10="","",_xll.BDP($A10&" Corp","INDUSTRY_SECTOR")) | F10: =IF($A10="","",PROPER(_xll.BDP($A10&" Corp","COUNTRY_FULL_NAME"))) | G10: =IF($A10="","",_xll.BDP($A10&" Corp","CRNCY")) | H10: =IF($A10="","",IFERROR(INDEX(SYZ_static!$T$2:$T$806,MATCH($A10,SYZ_static!$A$2:$A$806,0)),_xll.BDP($A10&" Corp","RTG_SP"))) | I10: =IF($A10="","",IFERROR(INDEX(SYZ_static!$S$2:$S$806,MATCH($A10,SYZ_static!$A$2:$A$806,0)),"")) | J10: =IF($A10="","",_xll.BDP($A10&" Corp","PAYMENT_RANK")) | K10: =IF($A10="","",_xll.BDP($A10&" Corp","CPN")) | L10: =IF($A10="","",_xll.BDP($A10&" Corp","MATURITY")) | M10: =IF($A10="","",IFERROR(_xll.BDP($A10&" Corp","MIN_PIECE")/1000,"")) | N10: =IF($A10="","",_xll.BDP($A10&" Corp","PX_LAST")) | O10: =IF($A10="","",_xll.BDP($A10&" Corp","YAS_BOND_YLD","YAS_YLD_FLAG=15")) | P10: =IF($A10="","",_xll.BDP($A10&" Corp","YAS_MOD_DUR")) | Q10: =IF($A10="","",_xll.BDP($A10&" Corp","YAS_OAS_SPRD")) | R10: =IF($A10="","",_xll.BDP($A10&" Corp","YAS_OAS_SPRD","SETTLE_DT",$B$2)) | S10: =IF($A10="","",IF(OR(NOT(ISNUMBER($Q10)),NOT(ISNUMBER($R10))),"",$Q10-$R10)) | T10: =IF($A10="","",_xll.BDP($A10&" Corp","YAS_BOND_YLD","YAS_YLD_FLAG=15","SETTLE_DT",$B$2)) | U10: =IF($A10="","",IF(OR(NOT(ISNUMBER($O10)),NOT(ISNUMBER($T10))),"",$O10-$T10)) | V10: =IF(NOT(ISNUMBER($S10)),"",COUNTIFS($G$7:$G$850,$G10,$S$7:$S$850,">"&$S10)+COUNTIFS($G$7:$G10,$G10,$S$7:$S10,$S10)) | W10: =IF(NOT(ISNUMBER($S10)),"",COUNTIFS($G$7:$G$850,$G10,$S$7:$S$850,"<"&$S10)+COUNTIFS($G$7:$G10,$G10,$S$7:$S10,$S10)) | X10: =IF($V10="","",$G10&"|"&$V10) | Y10: =IF($W10="","",$G10&"|"&$W10)
A11: US80386WAD74 | B11: =IF($A11="","",PROPER(_xll.BDP($A11&" Corp","NAME"))) | C11: =IF($A11="","",IFERROR(INDEX(Company_desc!$B$2:$B$1144,MATCH($A11,Company_desc!$A$2:$A$1144,0)),IFERROR(INDEX(SYZ_static!$Q$2:$Q$806,MATCH($A11,SYZ_static!$A$2:$A$806,0)),""))) | D11: =IF($A11="","",IFERROR(INDEX(SYZ_static!$B$2:$B$806,MATCH($A11,SYZ_static!$A$2:$A$806,0)),"")) | E11: =IF($A11="","",_xll.BDP($A11&" Corp","INDUSTRY_SECTOR")) | F11: =IF($A11="","",PROPER(_xll.BDP($A11&" Corp","COUNTRY_FULL_NAME"))) | G11: =IF($A11="","",_xll.BDP($A11&" Corp","CRNCY")) | H11: =IF($A11="","",IFERROR(INDEX(SYZ_static!$T$2:$T$806,MATCH($A11,SYZ_static!$A$2:$A$806,0)),_xll.BDP($A11&" Corp","RTG_SP"))) | I11: =IF($A11="","",IFERROR(INDEX(SYZ_static!$S$2:$S$806,MATCH($A11,SYZ_static!$A$2:$A$806,0)),"")) | J11: =IF($A11="","",_xll.BDP($A11&" Corp","PAYMENT_RANK")) | K11: =IF($A11="","",_xll.BDP($A11&" Corp","CPN")) | L11: =IF($A11="","",_xll.BDP($A11&" Corp","MATURITY")) | M11: =IF($A11="","",IFERROR(_xll.BDP($A11&" Corp","MIN_PIECE")/1000,"")) | N11: =IF($A11="","",_xll.BDP($A11&" Corp","PX_LAST")) | O11: =IF($A11="","",_xll.BDP($A11&" Corp","YAS_BOND_YLD","YAS_YLD_FLAG=15")) | P11: =IF($A11="","",_xll.BDP($A11&" Corp","YAS_MOD_DUR")) | Q11: =IF($A11="","",_xll.BDP($A11&" Corp","YAS_OAS_SPRD")) | R11: =IF($A11="","",_xll.BDP($A11&" Corp","YAS_OAS_SPRD","SETTLE_DT",$B$2)) | S11: =IF($A11="","",IF(OR(NOT(ISNUMBER($Q11)),NOT(ISNUMBER($R11))),"",$Q11-$R11)) | T11: =IF($A11="","",_xll.BDP($A11&" Corp","YAS_BOND_YLD","YAS_YLD_FLAG=15","SETTLE_DT",$B$2)) | U11: =IF($A11="","",IF(OR(NOT(ISNUMBER($O11)),NOT(ISNUMBER($T11))),"",$O11-$T11)) | V11: =IF(NOT(ISNUMBER($S11)),"",COUNTIFS($G$7:$G$850,$G11,$S$7:$S$850,">"&$S11)+COUNTIFS($G$7:$G11,$G11,$S$7:$S11,$S11)) | W11: =IF(NOT(ISNUMBER($S11)),"",COUNTIFS($G$7:$G$850,$G11,$S$7:$S$850,"<"&$S11)+COUNTIFS($G$7:$G11,$G11,$S$7:$S11,$S11)) | X11: =IF($V11="","",$G11&"|"&$V11) | Y11: =IF($W11="","",$G11&"|"&$W11)
A12: USG2583XAB76 | B12: =IF($A12="","",PROPER(_xll.BDP($A12&" Corp","NAME"))) | C12: =IF($A12="","",IFERROR(INDEX(Company_desc!$B$2:$B$1144,MATCH($A12,Company_desc!$A$2:$A$1144,0)),IFERROR(INDEX(SYZ_static!$Q$2:$Q$806,MATCH($A12,SYZ_static!$A$2:$A$806,0)),""))) | D12: =IF($A12="","",IFERROR(INDEX(SYZ_static!$B$2:$B$806,MATCH($A12,SYZ_static!$A$2:$A$806,0)),"")) | E12: =IF($A12="","",_xll.BDP($A12&" Corp","INDUSTRY_SECTOR")) | F12: =IF($A12="","",PROPER(_xll.BDP($A12&" Corp","COUNTRY_FULL_NAME"))) | G12: =IF($A12="","",_xll.BDP($A12&" Corp","CRNCY")) | H12: =IF($A12="","",IFERROR(INDEX(SYZ_static!$T$2:$T$806,MATCH($A12,SYZ_static!$A$2:$A$806,0)),_xll.BDP($A12&" Corp","RTG_SP"))) | I12: =IF($A12="","",IFERROR(INDEX(SYZ_static!$S$2:$S$806,MATCH($A12,SYZ_static!$A$2:$A$806,0)),"")) | J12: =IF($A12="","",_xll.BDP($A12&" Corp","PAYMENT_RANK")) | K12: =IF($A12="","",_xll.BDP($A12&" Corp","CPN")) | L12: =IF($A12="","",_xll.BDP($A12&" Corp","MATURITY")) | M12: =IF($A12="","",IFERROR(_xll.BDP($A12&" Corp","MIN_PIECE")/1000,"")) | N12: =IF($A12="","",_xll.BDP($A12&" Corp","PX_LAST")) | O12: =IF($A12="","",_xll.BDP($A12&" Corp","YAS_BOND_YLD","YAS_YLD_FLAG=15")) | P12: =IF($A12="","",_xll.BDP($A12&" Corp","YAS_MOD_DUR")) | Q12: =IF($A12="","",_xll.BDP($A12&" Corp","YAS_OAS_SPRD")) | R12: =IF($A12="","",_xll.BDP($A12&" Corp","YAS_OAS_SPRD","SETTLE_DT",$B$2)) | S12: =IF($A12="","",IF(OR(NOT(ISNUMBER($Q12)),NOT(ISNUMBER($R12))),"",$Q12-$R12)) | T12: =IF($A12="","",_xll.BDP($A12&" Corp","YAS_BOND_YLD","YAS_YLD_FLAG=15","SETTLE_DT",$B$2)) | U12: =IF($A12="","",IF(OR(NOT(ISNUMBER($O12)),NOT(ISNUMBER($T12))),"",$O12-$T12)) | V12: =IF(NOT(ISNUMBER($S12)),"",COUNTIFS($G$7:$G$850,$G12,$S$7:$S$850,">"&$S12)+COUNTIFS($G$7:$G12,$G12,$S$7:$S12,$S12)) | W12: =IF(NOT(ISNUMBER($S12)),"",COUNTIFS($G$7:$G$850,$G12,$S$7:$S$850,"<"&$S12)+COUNTIFS($G$7:$G12,$G12,$S$7:$S12,$S12)) | X12: =IF($V12="","",$G12&"|"&$V12) | Y12: =IF($W12="","",$G12&"|"&$W12)
A13: USE0R75RAB28 | B13: =IF($A13="","",PROPER(_xll.BDP($A13&" Corp","NAME"))) | C13: =IF($A13="","",IFERROR(INDEX(Company_desc!$B$2:$B$1144,MATCH($A13,Company_desc!$A$2:$A$1144,0)),IFERROR(INDEX(SYZ_static!$Q$2:$Q$806,MATCH($A13,SYZ_static!$A$2:$A$806,0)),""))) | D13: =IF($A13="","",IFERROR(INDEX(SYZ_static!$B$2:$B$806,MATCH($A13,SYZ_static!$A$2:$A$806,0)),"")) | E13: =IF($A13="","",_xll.BDP($A13&" Corp","INDUSTRY_SECTOR")) | F13: =IF($A13="","",PROPER(_xll.BDP($A13&" Corp","COUNTRY_FULL_NAME"))) | G13: =IF($A13="","",_xll.BDP($A13&" Corp","CRNCY")) | H13: =IF($A13="","",IFERROR(INDEX(SYZ_static!$T$2:$T$806,MATCH($A13,SYZ_static!$A$2:$A$806,0)),_xll.BDP($A13&" Corp","RTG_SP"))) | I13: =IF($A13="","",IFERROR(INDEX(SYZ_static!$S$2:$S$806,MATCH($A13,SYZ_static!$A$2:$A$806,0)),"")) | J13: =IF($A13="","",_xll.BDP($A13&" Corp","PAYMENT_RANK")) | K13: =IF($A13="","",_xll.BDP($A13&" Corp","CPN")) | L13: =IF($A13="","",_xll.BDP($A13&" Corp","MATURITY")) | M13: =IF($A13="","",IFERROR(_xll.BDP($A13&" Corp","MIN_PIECE")/1000,"")) | N13: =IF($A13="","",_xll.BDP($A13&" Corp","PX_LAST")) | O13: =IF($A13="","",_xll.BDP($A13&" Corp","YAS_BOND_YLD","YAS_YLD_FLAG=15")) | P13: =IF($A13="","",_xll.BDP($A13&" Corp","YAS_MOD_DUR")) | Q13: =IF($A13="","",_xll.BDP($A13&" Corp","YAS_OAS_SPRD")) | R13: =IF($A13="","",_xll.BDP($A13&" Corp","YAS_OAS_SPRD","SETTLE_DT",$B$2)) | S13: =IF($A13="","",IF(OR(NOT(ISNUMBER($Q13)),NOT(ISNUMBER($R13))),"",$Q13-$R13)) | T13: =IF($A13="","",_xll.BDP($A13&" Corp","YAS_BOND_YLD","YAS_YLD_FLAG=15","SETTLE_DT",$B$2)) | U13: =IF($A13="","",IF(OR(NOT(ISNUMBER($O13)),NOT(ISNUMBER($T13))),"",$O13-$T13)) | V13: =IF(NOT(ISNUMBER($S13)),"",COUNTIFS($G$7:$G$850,$G13,$S$7:$S$850,">"&$S13)+COUNTIFS($G$7:$G13,$G13,$S$7:$S13,$S13)) | W13: =IF(NOT(ISNUMBER($S13)),"",COUNTIFS($G$7:$G$850,$G13,$S$7:$S$850,"<"&$S13)+COUNTIFS($G$7:$G13,$G13,$S$7:$S13,$S13)) | X13: =IF($V13="","",$G13&"|"&$V13) | Y13: =IF($W13="","",$G13&"|"&$W13)
A14: USU8035UAC63 | B14: =IF($A14="","",PROPER(_xll.BDP($A14&" Corp","NAME"))) | C14: =IF($A14="","",IFERROR(INDEX(Company_desc!$B$2:$B$1144,MATCH($A14,Company_desc!$A$2:$A$1144,0)),IFERROR(INDEX(SYZ_static!$Q$2:$Q$806,MATCH($A14,SYZ_static!$A$2:$A$806,0)),""))) | D14: =IF($A14="","",IFERROR(INDEX(SYZ_static!$B$2:$B$806,MATCH($A14,SYZ_static!$A$2:$A$806,0)),"")) | E14: =IF($A14="","",_xll.BDP($A14&" Corp","INDUSTRY_SECTOR")) | F14: =IF($A14="","",PROPER(_xll.BDP($A14&" Corp","COUNTRY_FULL_NAME"))) | G14: =IF($A14="","",_xll.BDP($A14&" Corp","CRNCY")) | H14: =IF($A14="","",IFERROR(INDEX(SYZ_static!$T$2:$T$806,MATCH($A14,SYZ_static!$A$2:$A$806,0)),_xll.BDP($A14&" Corp","RTG_SP"))) | I14: =IF($A14="","",IFERROR(INDEX(SYZ_static!$S$2:$S$806,MATCH($A14,SYZ_static!$A$2:$A$806,0)),"")) | J14: =IF($A14="","",_xll.BDP($A14&" Corp","PAYMENT_RANK")) | K14: =IF($A14="","",_xll.BDP($A14&" Corp","CPN")) | L14: =IF($A14="","",_xll.BDP($A14&" Corp","MATURITY")) | M14: =IF($A14="","",IFERROR(_xll.BDP($A14&" Corp","MIN_PIECE")/1000,"")) | N14: =IF($A14="","",_xll.BDP($A14&" Corp","PX_LAST")) | O14: =IF($A14="","",_xll.BDP($A14&" Corp","YAS_BOND_YLD","YAS_YLD_FLAG=15")) | P14: =IF($A14="","",_xll.BDP($A14&" Corp","YAS_MOD_DUR")) | Q14: =IF($A14="","",_xll.BDP($A14&" Corp","YAS_OAS_SPRD")) | R14: =IF($A14="","",_xll.BDP($A14&" Corp","YAS_OAS_SPRD","SETTLE_DT",$B$2)) | S14: =IF($A14="","",IF(OR(NOT(ISNUMBER($Q14)),NOT(ISNUMBER($R14))),"",$Q14-$R14)) | T14: =IF($A14="","",_xll.BDP($A14&" Corp","YAS_BOND_YLD","YAS_YLD_FLAG=15","SETTLE_DT",$B$2)) | U14: =IF($A14="","",IF(OR(NOT(ISNUMBER($O14)),NOT(ISNUMBER($T14))),"",$O14-$T14)) | V14: =IF(NOT(ISNUMBER($S14)),"",COUNTIFS($G$7:$G$850,$G14,$S$7:$S$850,">"&$S14)+COUNTIFS($G$7:$G14,$G14,$S$7:$S14,$S14)) | W14: =IF(NOT(ISNUMBER($S14)),"",COUNTIFS($G$7:$G$850,$G14,$S$7:$S$850,"<"&$S14)+COUNTIFS($G$7:$G14,$G14,$S$7:$S14,$S14)) | X14: =IF($V14="","",$G14&"|"&$V14) | Y14: =IF($W14="","",$G14&"|"&$W14)
A15: CH0333827506 | B15: =IF($A15="","",PROPER(_xll.BDP($A15&" Corp","NAME"))) | C15: =IF($A15="","",IFERROR(INDEX(Company_desc!$B$2:$B$1144,MATCH($A15,Company_desc!$A$2:$A$1144,0)),IFERROR(INDEX(SYZ_static!$Q$2:$Q$806,MATCH($A15,SYZ_static!$A$2:$A$806,0)),""))) | D15: =IF($A15="","",IFERROR(INDEX(SYZ_static!$B$2:$B$806,MATCH($A15,SYZ_static!$A$2:$A$806,0)),"")) | E15: =IF($A15="","",_xll.BDP($A15&" Corp","INDUSTRY_SECTOR")) | F15: =IF($A15="","",PROPER(_xll.BDP($A15&" Corp","COUNTRY_FULL_NAME"))) | G15: =IF($A15="","",_xll.BDP($A15&" Corp","CRNCY")) | H15: =IF($A15="","",IFERROR(INDEX(SYZ_static!$T$2:$T$806,MATCH($A15,SYZ_static!$A$2:$A$806,0)),_xll.BDP($A15&" Corp","RTG_SP"))) | I15: =IF($A15="","",IFERROR(INDEX(SYZ_static!$S$2:$S$806,MATCH($A15,SYZ_static!$A$2:$A$806,0)),"")) | J15: =IF($A15="","",_xll.BDP($A15&" Corp","PAYMENT_RANK")) | K15: =IF($A15="","",_xll.BDP($A15&" Corp","CPN")) | L15: =IF($A15="","",_xll.BDP($A15&" Corp","MATURITY")) | M15: =IF($A15="","",IFERROR(_xll.BDP($A15&" Corp","MIN_PIECE")/1000,"")) | N15: =IF($A15="","",_xll.BDP($A15&" Corp","PX_LAST")) | O15: =IF($A15="","",_xll.BDP($A15&" Corp","YAS_BOND_YLD","YAS_YLD_FLAG=15")) | P15: =IF($A15="","",_xll.BDP($A15&" Corp","YAS_MOD_DUR")) | Q15: =IF($A15="","",_xll.BDP($A15&" Corp","YAS_OAS_SPRD")) | R15: =IF($A15="","",_xll.BDP($A15&" Corp","YAS_OAS_SPRD","SETTLE_DT",$B$2)) | S15: =IF($A15="","",IF(OR(NOT(ISNUMBER($Q15)),NOT(ISNUMBER($R15))),"",$Q15-$R15)) | T15: =IF($A15="","",_xll.BDP($A15&" Corp","YAS_BOND_YLD","YAS_YLD_FLAG=15","SETTLE_DT",$B$2)) | U15: =IF($A15="","",IF(OR(NOT(ISNUMBER($O15)),NOT(ISNUMBER($T15))),"",$O15-$T15)) | V15: =IF(NOT(ISNUMBER($S15)),"",COUNTIFS($G$7:$G$850,$G15,$S$7:$S$850,">"&$S15)+COUNTIFS($G$7:$G15,$G15,$S$7:$S15,$S15)) | W15: =IF(NOT(ISNUMBER($S15)),"",COUNTIFS($G$7:$G$850,$G15,$S$7:$S$850,"<"&$S15)+COUNTIFS($G$7:$G15,$G15,$S$7:$S15,$S15)) | X15: =IF($V15="","",$G15&"|"&$V15) | Y15: =IF($W15="","",$G15&"|"&$W15)
A16: USU8215LAA27 | B16: =IF($A16="","",PROPER(_xll.BDP($A16&" Corp","NAME"))) | C16: =IF($A16="","",IFERROR(INDEX(Company_desc!$B$2:$B$1144,MATCH($A16,Company_desc!$A$2:$A$1144,0)),IFERROR(INDEX(SYZ_static!$Q$2:$Q$806,MATCH($A16,SYZ_static!$A$2:$A$806,0)),""))) | D16: =IF($A16="","",IFERROR(INDEX(SYZ_static!$B$2:$B$806,MATCH($A16,SYZ_static!$A$2:$A$806,0)),"")) | E16: =IF($A16="","",_xll.BDP($A16&" Corp","INDUSTRY_SECTOR")) | F16: =IF($A16="","",PROPER(_xll.BDP($A16&" Corp","COUNTRY_FULL_NAME"))) | G16: =IF($A16="","",_xll.BDP($A16&" Corp","CRNCY")) | H16: =IF($A16="","",IFERROR(INDEX(SYZ_static!$T$2:$T$806,MATCH($A16,SYZ_static!$A$2:$A$806,0)),_xll.BDP($A16&" Corp","RTG_SP"))) | I16: =IF($A16="","",IFERROR(INDEX(SYZ_static!$S$2:$S$806,MATCH($A16,SYZ_static!$A$2:$A$806,0)),"")) | J16: =IF($A16="","",_xll.BDP($A16&" Corp","PAYMENT_RANK")) | K16: =IF($A16="","",_xll.BDP($A16&" Corp","CPN")) | L16: =IF($A16="","",_xll.BDP($A16&" Corp","MATURITY")) | M16: =IF($A16="","",IFERROR(_xll.BDP($A16&" Corp","MIN_PIECE")/1000,"")) | N16: =IF($A16="","",_xll.BDP($A16&" Corp","PX_LAST")) | O16: =IF($A16="","",_xll.BDP($A16&" Corp","YAS_BOND_YLD","YAS_YLD_FLAG=15")) | P16: =IF($A16="","",_xll.BDP($A16&" Corp","YAS_MOD_DUR")) | Q16: =IF($A16="","",_xll.BDP($A16&" Corp","YAS_OAS_SPRD")) | R16: =IF($A16="","",_xll.BDP($A16&" Corp","YAS_OAS_SPRD","SETTLE_DT",$B$2)) | S16: =IF($A16="","",IF(OR(NOT(ISNUMBER($Q16)),NOT(ISNUMBER($R16))),"",$Q16-$R16)) | T16: =IF($A16="","",_xll.BDP($A16&" Corp","YAS_BOND_YLD","YAS_YLD_FLAG=15","SETTLE_DT",$B$2)) | U16: =IF($A16="","",IF(OR(NOT(ISNUMBER($O16)),NOT(ISNUMBER($T16))),"",$O16-$T16)) | V16: =IF(NOT(ISNUMBER($S16)),"",COUNTIFS($G$7:$G$850,$G16,$S$7:$S$850,">"&$S16)+COUNTIFS($G$7:$G16,$G16,$S$7:$S16,$S16)) | W16: =IF(NOT(ISNUMBER($S16)),"",COUNTIFS($G$7:$G$850,$G16,$S$7:$S$850,"<"&$S16)+COUNTIFS($G$7:$G16,$G16,$S$7:$S16,$S16)) | X16: =IF($V16="","",$G16&"|"&$V16) | Y16: =IF($W16="","",$G16&"|"&$W16)
A17: FR001400QC85 | B17: =IF($A17="","",PROPER(_xll.BDP($A17&" Corp","NAME"))) | C17: =IF($A17="","",IFERROR(INDEX(Company_desc!$B$2:$B$1144,MATCH($A17,Company_desc!$A$2:$A$1144,0)),IFERROR(INDEX(SYZ_static!$Q$2:$Q$806,MATCH($A17,SYZ_static!$A$2:$A$806,0)),""))) | D17: =IF($A17="","",IFERROR(INDEX(SYZ_static!$B$2:$B$806,MATCH($A17,SYZ_static!$A$2:$A$806,0)),"")) | E17: =IF($A17="","",_xll.BDP($A17&" Corp","INDUSTRY_SECTOR")) | F17: =IF($A17="","",PROPER(_xll.BDP($A17&" Corp","COUNTRY_FULL_NAME"))) | G17: =IF($A17="","",_xll.BDP($A17&" Corp","CRNCY")) | H17: =IF($A17="","",IFERROR(INDEX(SYZ_static!$T$2:$T$806,MATCH($A17,SYZ_static!$A$2:$A$806,0)),_xll.BDP($A17&" Corp","RTG_SP"))) | I17: =IF($A17="","",IFERROR(INDEX(SYZ_static!$S$2:$S$806,MATCH($A17,SYZ_static!$A$2:$A$806,0)),"")) | J17: =IF($A17="","",_xll.BDP($A17&" Corp","PAYMENT_RANK")) | K17: =IF($A17="","",_xll.BDP($A17&" Corp","CPN")) | L17: =IF($A17="","",_xll.BDP($A17&" Corp","MATURITY")) | M17: =IF($A17="","",IFERROR(_xll.BDP($A17&" Corp","MIN_PIECE")/1000,"")) | N17: =IF($A17="","",_xll.BDP($A17&" Corp","PX_LAST")) | O17: =IF($A17="","",_xll.BDP($A17&" Corp","YAS_BOND_YLD","YAS_YLD_FLAG=15")) | P17: =IF($A17="","",_xll.BDP($A17&" Corp","YAS_MOD_DUR")) | Q17: =IF($A17="","",_xll.BDP($A17&" Corp","YAS_OAS_SPRD")) | R17: =IF($A17="","",_xll.BDP($A17&" Corp","YAS_OAS_SPRD","SETTLE_DT",$B$2)) | S17: =IF($A17="","",IF(OR(NOT(ISNUMBER($Q17)),NOT(ISNUMBER($R17))),"",$Q17-$R17)) | T17: =IF($A17="","",_xll.BDP($A17&" Corp","YAS_BOND_YLD","YAS_YLD_FLAG=15","SETTLE_DT",$B$2)) | U17: =IF($A17="","",IF(OR(NOT(ISNUMBER($O17)),NOT(ISNUMBER($T17))),"",$O17-$T17)) | V17: =IF(NOT(ISNUMBER($S17)),"",COUNTIFS($G$7:$G$850,$G17,$S$7:$S$850,">"&$S17)+COUNTIFS($G$7:$G17,$G17,$S$7:$S17,$S17)) | W17: =IF(NOT(ISNUMBER($S17)),"",COUNTIFS($G$7:$G$850,$G17,$S$7:$S$850,"<"&$S17)+COUNTIFS($G$7:$G17,$G17,$S$7:$S17,$S17)) | X17: =IF($V17="","",$G17&"|"&$V17) | Y17: =IF($W17="","",$G17&"|"&$W17)
A18: FR001400HZE3 | B18: =IF($A18="","",PROPER(_xll.BDP($A18&" Corp","NAME"))) | C18: =IF($A18="","",IFERROR(INDEX(Company_desc!$B$2:$B$1144,MATCH($A18,Company_desc!$A$2:$A$1144,0)),IFERROR(INDEX(SYZ_static!$Q$2:$Q$806,MATCH($A18,SYZ_static!$A$2:$A$806,0)),""))) | D18: =IF($A18="","",IFERROR(INDEX(SYZ_static!$B$2:$B$806,MATCH($A18,SYZ_static!$A$2:$A$806,0)),"")) | E18: =IF($A18="","",_xll.BDP($A18&" Corp","INDUSTRY_SECTOR")) | F18: =IF($A18="","",PROPER(_xll.BDP($A18&" Corp","COUNTRY_FULL_NAME"))) | G18: =IF($A18="","",_xll.BDP($A18&" Corp","CRNCY")) | H18: =IF($A18="","",IFERROR(INDEX(SYZ_static!$T$2:$T$806,MATCH($A18,SYZ_static!$A$2:$A$806,0)),_xll.BDP($A18&" Corp","RTG_SP"))) | I18: =IF($A18="","",IFERROR(INDEX(SYZ_static!$S$2:$S$806,MATCH($A18,SYZ_static!$A$2:$A$806,0)),"")) | J18: =IF($A18="","",_xll.BDP($A18&" Corp","PAYMENT_RANK")) | K18: =IF($A18="","",_xll.BDP($A18&" Corp","CPN")) | L18: =IF($A18="","",_xll.BDP($A18&" Corp","MATURITY")) | M18: =IF($A18="","",IFERROR(_xll.BDP($A18&" Corp","MIN_PIECE")/1000,"")) | N18: =IF($A18="","",_xll.BDP($A18&" Corp","PX_LAST")) | O18: =IF($A18="","",_xll.BDP($A18&" Corp","YAS_BOND_YLD","YAS_YLD_FLAG=15")) | P18: =IF($A18="","",_xll.BDP($A18&" Corp","YAS_MOD_DUR")) | Q18: =IF($A18="","",_xll.BDP($A18&" Corp","YAS_OAS_SPRD")) | R18: =IF($A18="","",_xll.BDP($A18&" Corp","YAS_OAS_SPRD","SETTLE_DT",$B$2)) | S18: =IF($A18="","",IF(OR(NOT(ISNUMBER($Q18)),NOT(ISNUMBER($R18))),"",$Q18-$R18)) | T18: =IF($A18="","",_xll.BDP($A18&" Corp","YAS_BOND_YLD","YAS_YLD_FLAG=15","SETTLE_DT",$B$2)) | U18: =IF($A18="","",IF(OR(NOT(ISNUMBER($O18)),NOT(ISNUMBER($T18))),"",$O18-$T18)) | V18: =IF(NOT(ISNUMBER($S18)),"",COUNTIFS($G$7:$G$850,$G18,$S$7:$S$850,">"&$S18)+COUNTIFS($G$7:$G18,$G18,$S$7:$S18,$S18)) | W18: =IF(NOT(ISNUMBER($S18)),"",COUNTIFS($G$7:$G$850,$G18,$S$7:$S$850,"<"&$S18)+COUNTIFS($G$7:$G18,$G18,$S$7:$S18,$S18)) | X18: =IF($V18="","",$G18&"|"&$V18) | Y18: =IF($W18="","",$G18&"|"&$W18)
... A769: US04636NAR44 | B769: =IF($A769="","",PROPER(_xll.BDP($A769&" Corp","NAME"))) | C769: =IF($A769="","",IFERROR(INDEX(Company_desc!$B$2:$B$1144,MATCH($A769,Company_desc!$A$2:$A$1144,0)),IFERROR(INDEX(SYZ_static!$Q$2:$Q$806,MATCH($A769,SYZ_static!$A$2:$A$806,0)),""))) | D769: =IF($A769="","",IFERROR(INDEX(SYZ_static!$B$2:$B$806,MATCH($A769,SYZ_static!$A$2:$A$806,0)),"")) | E769: =IF($A769="","",_xll.BDP($A769&" Corp","INDUSTRY_SECTOR")) | F769: =IF($A769="","",PROPER(_xll.BDP($A769&" Corp","COUNTRY_FULL_NAME"))) | G769: =IF($A769="","",_xll.BDP($A769&" Corp","CRNCY")) | H769: =IF($A769="","",IFERROR(INDEX(SYZ_static!$T$2:$T$806,MATCH($A769,SYZ_static!$A$2:$A$806,0)),_xll.BDP($A769&" Corp","RTG_SP"))) | I769: =IF($A769="","",IFERROR(INDEX(SYZ_static!$S$2:$S$806,MATCH($A769,SYZ_static!$A$2:$A$806,0)),"")) | J769: =IF($A769="","",_xll.BDP($A769&" Corp","PAYMENT_RANK")) | K769: =IF($A769="","",_xll.BDP($A769&" Corp","CPN")) | L769: =IF($A769="","",_xll.BDP($A769&" Corp","MATURITY")) | M769: =IF($A769="","",IFERROR(_xll.BDP($A769&" Corp","MIN_PIECE")/1000,"")) | N769: =IF($A769="","",_xll.BDP($A769&" Corp","PX_LAST")) | O769: =IF($A769="","",_xll.BDP($A769&" Corp","YAS_BOND_YLD","YAS_YLD_FLAG=15")) | P769: =IF($A769="","",_xll.BDP($A769&" Corp","YAS_MOD_DUR")) | Q769: =IF($A769="","",_xll.BDP($A769&" Corp","YAS_OAS_SPRD")) | R769: =IF($A769="","",_xll.BDP($A769&" Corp","YAS_OAS_SPRD","SETTLE_DT",$B$2)) | S769: =IF($A769="","",IF(OR(NOT(ISNUMBER($Q769)),NOT(ISNUMBER($R769))),"",$Q769-$R769)) | T769: =IF($A769="","",_xll.BDP($A769&" Corp","YAS_BOND_YLD","YAS_YLD_FLAG=15","SETTLE_DT",$B$2)) | U769: =IF($A769="","",IF(OR(NOT(ISNUMBER($O769)),NOT(ISNUMBER($T769))),"",$O769-$T769)) | V769: =IF(NOT(ISNUMBER($S769)),"",COUNTIFS($G$7:$G$850,$G769,$S$7:$S$850,">"&$S769)+COUNTIFS($G$7:$G769,$G769,$S$7:$S769,$S769)) | W769: =IF(NOT(ISNUMBER($S769)),"",COUNTIFS($G$7:$G$850,$G769,$S$7:$S$850,"<"&$S769)+COUNTIFS($G$7:$G769,$G769,$S$7:$S769,$S769)) | X769: =IF($V769="","",$G769&"|"&$V769) | Y769: =IF($W769="","",$G769&"|"&$W769)
B770: =IF($A770="","",PROPER(_xll.BDP($A770&" Corp","NAME"))) | C770: =IF($A770="","",IFERROR(INDEX(Company_desc!$B$2:$B$1144,MATCH($A770,Company_desc!$A$2:$A$1144,0)),IFERROR(INDEX(SYZ_static!$Q$2:$Q$806,MATCH($A770,SYZ_static!$A$2:$A$806,0)),""))) | D770: =IF($A770="","",IFERROR(INDEX(SYZ_static!$B$2:$B$806,MATCH($A770,SYZ_static!$A$2:$A$806,0)),"")) | E770: =IF($A770="","",_xll.BDP($A770&" Corp","INDUSTRY_SECTOR")) | F770: =IF($A770="","",PROPER(_xll.BDP($A770&" Corp","COUNTRY_FULL_NAME"))) | G770: =IF($A770="","",_xll.BDP($A770&" Corp","CRNCY")) | H770: =IF($A770="","",IFERROR(INDEX(SYZ_static!$T$2:$T$806,MATCH($A770,SYZ_static!$A$2:$A$806,0)),_xll.BDP($A770&" Corp","RTG_SP"))) | I770: =IF($A770="","",IFERROR(INDEX(SYZ_static!$S$2:$S$806,MATCH($A770,SYZ_static!$A$2:$A$806,0)),"")) | J770: =IF($A770="","",_xll.BDP($A770&" Corp","PAYMENT_RANK")) | K770: =IF($A770="","",_xll.BDP($A770&" Corp","CPN")) | L770: =IF($A770="","",_xll.BDP($A770&" Corp","MATURITY")) | M770: =IF($A770="","",IFERROR(_xll.BDP($A770&" Corp","MIN_PIECE")/1000,"")) | N770: =IF($A770="","",_xll.BDP($A770&" Corp","PX_LAST")) | O770: =IF($A770="","",_xll.BDP($A770&" Corp","YAS_BOND_YLD","YAS_YLD_FLAG=15")) | P770: =IF($A770="","",_xll.BDP($A770&" Corp","YAS_MOD_DUR")) | Q770: =IF($A770="","",_xll.BDP($A770&" Corp","YAS_OAS_SPRD")) | R770: =IF($A770="","",_xll.BDP($A770&" Corp","YAS_OAS_SPRD","SETTLE_DT",$B$2)) | S770: =IF($A770="","",IF(OR(NOT(ISNUMBER($Q770)),NOT(ISNUMBER($R770))),"",$Q770-$R770)) | T770: =IF($A770="","",_xll.BDP($A770&" Corp","YAS_BOND_YLD","YAS_YLD_FLAG=15","SETTLE_DT",$B$2)) | U770: =IF($A770="","",IF(OR(NOT(ISNUMBER($O770)),NOT(ISNUMBER($T770))),"",$O770-$T770)) | V770: =IF(NOT(ISNUMBER($S770)),"",COUNTIFS($G$7:$G$850,$G770,$S$7:$S$850,">"&$S770)+COUNTIFS($G$7:$G770,$G770,$S$7:$S770,$S770)) | W770: =IF(NOT(ISNUMBER($S770)),"",COUNTIFS($G$7:$G$850,$G770,$S$7:$S$850,"<"&$S770)+COUNTIFS($G$7:$G770,$G770,$S$7:$S770,$S770)) | X770: =IF($V770="","",$G770&"|"&$V770) | Y770: =IF($W770="","",$G770&"|"&$W770)
B771: =IF($A771="","",PROPER(_xll.BDP($A771&" Corp","NAME"))) | C771: =IF($A771="","",IFERROR(INDEX(Company_desc!$B$2:$B$1144,MATCH($A771,Company_desc!$A$2:$A$1144,0)),IFERROR(INDEX(SYZ_static!$Q$2:$Q$806,MATCH($A771,SYZ_static!$A$2:$A$806,0)),""))) | D771: =IF($A771="","",IFERROR(INDEX(SYZ_static!$B$2:$B$806,MATCH($A771,SYZ_static!$A$2:$A$806,0)),"")) | E771: =IF($A771="","",_xll.BDP($A771&" Corp","INDUSTRY_SECTOR")) | F771: =IF($A771="","",PROPER(_xll.BDP($A771&" Corp","COUNTRY_FULL_NAME"))) | G771: =IF($A771="","",_xll.BDP($A771&" Corp","CRNCY")) | H771: =IF($A771="","",IFERROR(INDEX(SYZ_static!$T$2:$T$806,MATCH($A771,SYZ_static!$A$2:$A$806,0)),_xll.BDP($A771&" Corp","RTG_SP"))) | I771: =IF($A771="","",IFERROR(INDEX(SYZ_static!$S$2:$S$806,MATCH($A771,SYZ_static!$A$2:$A$806,0)),"")) | J771: =IF($A771="","",_xll.BDP($A771&" Corp","PAYMENT_RANK")) | K771: =IF($A771="","",_xll.BDP($A771&" Corp","CPN")) | L771: =IF($A771="","",_xll.BDP($A771&" Corp","MATURITY")) | M771: =IF($A771="","",IFERROR(_xll.BDP($A771&" Corp","MIN_PIECE")/1000,"")) | N771: =IF($A771="","",_xll.BDP($A771&" Corp","PX_LAST")) | O771: =IF($A771="","",_xll.BDP($A771&" Corp","YAS_BOND_YLD","YAS_YLD_FLAG=15")) | P771: =IF($A771="","",_xll.BDP($A771&" Corp","YAS_MOD_DUR")) | Q771: =IF($A771="","",_xll.BDP($A771&" Corp","YAS_OAS_SPRD")) | R771: =IF($A771="","",_xll.BDP($A771&" Corp","YAS_OAS_SPRD","SETTLE_DT",$B$2)) | S771: =IF($A771="","",IF(OR(NOT(ISNUMBER($Q771)),NOT(ISNUMBER($R771))),"",$Q771-$R771)) | T771: =IF($A771="","",_xll.BDP($A771&" Corp","YAS_BOND_YLD","YAS_YLD_FLAG=15","SETTLE_DT",$B$2)) | U771: =IF($A771="","",IF(OR(NOT(ISNUMBER($O771)),NOT(ISNUMBER($T771))),"",$O771-$T771)) | V771: =IF(NOT(ISNUMBER($S771)),"",COUNTIFS($G$7:$G$850,$G771,$S$7:$S$850,">"&$S771)+COUNTIFS($G$7:$G771,$G771,$S$7:$S771,$S771)) | W771: =IF(NOT(ISNUMBER($S771)),"",COUNTIFS($G$7:$G$850,$G771,$S$7:$S$850,"<"&$S771)+COUNTIFS($G$7:$G771,$G771,$S$7:$S771,$S771)) | X771: =IF($V771="","",$G771&"|"&$V771) | Y771: =IF($W771="","",$G771&"|"&$W771)
B772: =IF($A772="","",PROPER(_xll.BDP($A772&" Corp","NAME"))) | C772: =IF($A772="","",IFERROR(INDEX(Company_desc!$B$2:$B$1144,MATCH($A772,Company_desc!$A$2:$A$1144,0)),IFERROR(INDEX(SYZ_static!$Q$2:$Q$806,MATCH($A772,SYZ_static!$A$2:$A$806,0)),""))) | D772: =IF($A772="","",IFERROR(INDEX(SYZ_static!$B$2:$B$806,MATCH($A772,SYZ_static!$A$2:$A$806,0)),"")) | E772: =IF($A772="","",_xll.BDP($A772&" Corp","INDUSTRY_SECTOR")) | F772: =IF($A772="","",PROPER(_xll.BDP($A772&" Corp","COUNTRY_FULL_NAME"))) | G772: =IF($A772="","",_xll.BDP($A772&" Corp","CRNCY")) | H772: =IF($A772="","",IFERROR(INDEX(SYZ_static!$T$2:$T$806,MATCH($A772,SYZ_static!$A$2:$A$806,0)),_xll.BDP($A772&" Corp","RTG_SP"))) | I772: =IF($A772="","",IFERROR(INDEX(SYZ_static!$S$2:$S$806,MATCH($A772,SYZ_static!$A$2:$A$806,0)),"")) | J772: =IF($A772="","",_xll.BDP($A772&" Corp","PAYMENT_RANK")) | K772: =IF($A772="","",_xll.BDP($A772&" Corp","CPN")) | L772: =IF($A772="","",_xll.BDP($A772&" Corp","MATURITY")) | M772: =IF($A772="","",IFERROR(_xll.BDP($A772&" Corp","MIN_PIECE")/1000,"")) | N772: =IF($A772="","",_xll.BDP($A772&" Corp","PX_LAST")) | O772: =IF($A772="","",_xll.BDP($A772&" Corp","YAS_BOND_YLD","YAS_YLD_FLAG=15")) | P772: =IF($A772="","",_xll.BDP($A772&" Corp","YAS_MOD_DUR")) | Q772: =IF($A772="","",_xll.BDP($A772&" Corp","YAS_OAS_SPRD")) | R772: =IF($A772="","",_xll.BDP($A772&" Corp","YAS_OAS_SPRD","SETTLE_DT",$B$2)) | S772: =IF($A772="","",IF(OR(NOT(ISNUMBER($Q772)),NOT(ISNUMBER($R772))),"",$Q772-$R772)) | T772: =IF($A772="","",_xll.BDP($A772&" Corp","YAS_BOND_YLD","YAS_YLD_FLAG=15","SETTLE_DT",$B$2)) | U772: =IF($A772="","",IF(OR(NOT(ISNUMBER($O772)),NOT(ISNUMBER($T772))),"",$O772-$T772)) | V772: =IF(NOT(ISNUMBER($S772)),"",COUNTIFS($G$7:$G$850,$G772,$S$7:$S$850,">"&$S772)+COUNTIFS($G$7:$G772,$G772,$S$7:$S772,$S772)) | W772: =IF(NOT(ISNUMBER($S772)),"",COUNTIFS($G$7:$G$850,$G772,$S$7:$S$850,"<"&$S772)+COUNTIFS($G$7:$G772,$G772,$S$7:$S772,$S772)) | X772: =IF($V772="","",$G772&"|"&$V772) | Y772: =IF($W772="","",$G772&"|"&$W772)
B773: =IF($A773="","",PROPER(_xll.BDP($A773&" Corp","NAME"))) | C773: =IF($A773="","",IFERROR(INDEX(Company_desc!$B$2:$B$1144,MATCH($A773,Company_desc!$A$2:$A$1144,0)),IFERROR(INDEX(SYZ_static!$Q$2:$Q$806,MATCH($A773,SYZ_static!$A$2:$A$806,0)),""))) | D773: =IF($A773="","",IFERROR(INDEX(SYZ_static!$B$2:$B$806,MATCH($A773,SYZ_static!$A$2:$A$806,0)),"")) | E773: =IF($A773="","",_xll.BDP($A773&" Corp","INDUSTRY_SECTOR")) | F773: =IF($A773="","",PROPER(_xll.BDP($A773&" Corp","COUNTRY_FULL_NAME"))) | G773: =IF($A773="","",_xll.BDP($A773&" Corp","CRNCY")) | H773: =IF($A773="","",IFERROR(INDEX(SYZ_static!$T$2:$T$806,MATCH($A773,SYZ_static!$A$2:$A$806,0)),_xll.BDP($A773&" Corp","RTG_SP"))) | I773: =IF($A773="","",IFERROR(INDEX(SYZ_static!$S$2:$S$806,MATCH($A773,SYZ_static!$A$2:$A$806,0)),"")) | J773: =IF($A773="","",_xll.BDP($A773&" Corp","PAYMENT_RANK")) | K773: =IF($A773="","",_xll.BDP($A773&" Corp","CPN")) | L773: =IF($A773="","",_xll.BDP($A773&" Corp","MATURITY")) | M773: =IF($A773="","",IFERROR(_xll.BDP($A773&" Corp","MIN_PIECE")/1000,"")) | N773: =IF($A773="","",_xll.BDP($A773&" Corp","PX_LAST")) | O773: =IF($A773="","",_xll.BDP($A773&" Corp","YAS_BOND_YLD","YAS_YLD_FLAG=15")) | P773: =IF($A773="","",_xll.BDP($A773&" Corp","YAS_MOD_DUR")) | Q773: =IF($A773="","",_xll.BDP($A773&" Corp","YAS_OAS_SPRD")) | R773: =IF($A773="","",_xll.BDP($A773&" Corp","YAS_OAS_SPRD","SETTLE_DT",$B$2)) | S773: =IF($A773="","",IF(OR(NOT(ISNUMBER($Q773)),NOT(ISNUMBER($R773))),"",$Q773-$R773)) | T773: =IF($A773="","",_xll.BDP($A773&" Corp","YAS_BOND_YLD","YAS_YLD_FLAG=15","SETTLE_DT",$B$2)) | U773: =IF($A773="","",IF(OR(NOT(ISNUMBER($O773)),NOT(ISNUMBER($T773))),"",$O773-$T773)) | V773: =IF(NOT(ISNUMBER($S773)),"",COUNTIFS($G$7:$G$850,$G773,$S$7:$S$850,">"&$S773)+COUNTIFS($G$7:$G773,$G773,$S$7:$S773,$S773)) | W773: =IF(NOT(ISNUMBER($S773)),"",COUNTIFS($G$7:$G$850,$G773,$S$7:$S$850,"<"&$S773)+COUNTIFS($G$7:$G773,$G773,$S$7:$S773,$S773)) | X773: =IF($V773="","",$G773&"|"&$V773) | Y773: =IF($W773="","",$G773&"|"&$W773)
B774: =IF($A774="","",PROPER(_xll.BDP($A774&" Corp","NAME"))) | C774: =IF($A774="","",IFERROR(INDEX(Company_desc!$B$2:$B$1144,MATCH($A774,Company_desc!$A$2:$A$1144,0)),IFERROR(INDEX(SYZ_static!$Q$2:$Q$806,MATCH($A774,SYZ_static!$A$2:$A$806,0)),""))) | D774: =IF($A774="","",IFERROR(INDEX(SYZ_static!$B$2:$B$806,MATCH($A774,SYZ_static!$A$2:$A$806,0)),"")) | E774: =IF($A774="","",_xll.BDP($A774&" Corp","INDUSTRY_SECTOR")) | F774: =IF($A774="","",PROPER(_xll.BDP($A774&" Corp","COUNTRY_FULL_NAME"))) | G774: =IF($A774="","",_xll.BDP($A774&" Corp","CRNCY")) | H774: =IF($A774="","",IFERROR(INDEX(SYZ_static!$T$2:$T$806,MATCH($A774,SYZ_static!$A$2:$A$806,0)),_xll.BDP($A774&" Corp","RTG_SP"))) | I774: =IF($A774="","",IFERROR(INDEX(SYZ_static!$S$2:$S$806,MATCH($A774,SYZ_static!$A$2:$A$806,0)),"")) | J774: =IF($A774="","",_xll.BDP($A774&" Corp","PAYMENT_RANK")) | K774: =IF($A774="","",_xll.BDP($A774&" Corp","CPN")) | L774: =IF($A774="","",_xll.BDP($A774&" Corp","MATURITY")) | M774: =IF($A774="","",IFERROR(_xll.BDP($A774&" Corp","MIN_PIECE")/1000,"")) | N774: =IF($A774="","",_xll.BDP($A774&" Corp","PX_LAST")) | O774: =IF($A774="","",_xll.BDP($A774&" Corp","YAS_BOND_YLD","YAS_YLD_FLAG=15")) | P774: =IF($A774="","",_xll.BDP($A774&" Corp","YAS_MOD_DUR")) | Q774: =IF($A774="","",_xll.BDP($A774&" Corp","YAS_OAS_SPRD")) | R774: =IF($A774="","",_xll.BDP($A774&" Corp","YAS_OAS_SPRD","SETTLE_DT",$B$2)) | S774: =IF($A774="","",IF(OR(NOT(ISNUMBER($Q774)),NOT(ISNUMBER($R774))),"",$Q774-$R774)) | T774: =IF($A774="","",_xll.BDP($A774&" Corp","YAS_BOND_YLD","YAS_YLD_FLAG=15","SETTLE_DT",$B$2)) | U774: =IF($A774="","",IF(OR(NOT(ISNUMBER($O774)),NOT(ISNUMBER($T774))),"",$O774-$T774)) | V774: =IF(NOT(ISNUMBER($S774)),"",COUNTIFS($G$7:$G$850,$G774,$S$7:$S$850,">"&$S774)+COUNTIFS($G$7:$G774,$G774,$S$7:$S774,$S774)) | W774: =IF(NOT(ISNUMBER($S774)),"",COUNTIFS($G$7:$G$850,$G774,$S$7:$S$850,"<"&$S774)+COUNTIFS($G$7:$G774,$G774,$S$7:$S774,$S774)) | X774: =IF($V774="","",$G774&"|"&$V774) | Y774: =IF($W774="","",$G774&"|"&$W774)
B775: =IF($A775="","",PROPER(_xll.BDP($A775&" Corp","NAME"))) | C775: =IF($A775="","",IFERROR(INDEX(Company_desc!$B$2:$B$1144,MATCH($A775,Company_desc!$A$2:$A$1144,0)),IFERROR(INDEX(SYZ_static!$Q$2:$Q$806,MATCH($A775,SYZ_static!$A$2:$A$806,0)),""))) | D775: =IF($A775="","",IFERROR(INDEX(SYZ_static!$B$2:$B$806,MATCH($A775,SYZ_static!$A$2:$A$806,0)),"")) | E775: =IF($A775="","",_xll.BDP($A775&" Corp","INDUSTRY_SECTOR")) | F775: =IF($A775="","",PROPER(_xll.BDP($A775&" Corp","COUNTRY_FULL_NAME"))) | G775: =IF($A775="","",_xll.BDP($A775&" Corp","CRNCY")) | H775: =IF($A775="","",IFERROR(INDEX(SYZ_static!$T$2:$T$806,MATCH($A775,SYZ_static!$A$2:$A$806,0)),_xll.BDP($A775&" Corp","RTG_SP"))) | I775: =IF($A775="","",IFERROR(INDEX(SYZ_static!$S$2:$S$806,MATCH($A775,SYZ_static!$A$2:$A$806,0)),"")) | J775: =IF($A775="","",_xll.BDP($A775&" Corp","PAYMENT_RANK")) | K775: =IF($A775="","",_xll.BDP($A775&" Corp","CPN")) | L775: =IF($A775="","",_xll.BDP($A775&" Corp","MATURITY")) | M775: =IF($A775="","",IFERROR(_xll.BDP($A775&" Corp","MIN_PIECE")/1000,"")) | N775: =IF($A775="","",_xll.BDP($A775&" Corp","PX_LAST")) | O775: =IF($A775="","",_xll.BDP($A775&" Corp","YAS_BOND_YLD","YAS_YLD_FLAG=15")) | P775: =IF($A775="","",_xll.BDP($A775&" Corp","YAS_MOD_DUR")) | Q775: =IF($A775="","",_xll.BDP($A775&" Corp","YAS_OAS_SPRD")) | R775: =IF($A775="","",_xll.BDP($A775&" Corp","YAS_OAS_SPRD","SETTLE_DT",$B$2)) | S775: =IF($A775="","",IF(OR(NOT(ISNUMBER($Q775)),NOT(ISNUMBER($R775))),"",$Q775-$R775)) | T775: =IF($A775="","",_xll.BDP($A775&" Corp","YAS_BOND_YLD","YAS_YLD_FLAG=15","SETTLE_DT",$B$2)) | U775: =IF($A775="","",IF(OR(NOT(ISNUMBER($O775)),NOT(ISNUMBER($T775))),"",$O775-$T775)) | V775: =IF(NOT(ISNUMBER($S775)),"",COUNTIFS($G$7:$G$850,$G775,$S$7:$S$850,">"&$S775)+COUNTIFS($G$7:$G775,$G775,$S$7:$S775,$S775)) | W775: =IF(NOT(ISNUMBER($S775)),"",COUNTIFS($G$7:$G$850,$G775,$S$7:$S$850,"<"&$S775)+COUNTIFS($G$7:$G775,$G775,$S$7:$S775,$S775)) | X775: =IF($V775="","",$G775&"|"&$V775) | Y775: =IF($W775="","",$G775&"|"&$W775)
B776: =IF($A776="","",PROPER(_xll.BDP($A776&" Corp","NAME"))) | C776: =IF($A776="","",IFERROR(INDEX(Company_desc!$B$2:$B$1144,MATCH($A776,Company_desc!$A$2:$A$1144,0)),IFERROR(INDEX(SYZ_static!$Q$2:$Q$806,MATCH($A776,SYZ_static!$A$2:$A$806,0)),""))) | D776: =IF($A776="","",IFERROR(INDEX(SYZ_static!$B$2:$B$806,MATCH($A776,SYZ_static!$A$2:$A$806,0)),"")) | E776: =IF($A776="","",_xll.BDP($A776&" Corp","INDUSTRY_SECTOR")) | F776: =IF($A776="","",PROPER(_xll.BDP($A776&" Corp","COUNTRY_FULL_NAME"))) | G776: =IF($A776="","",_xll.BDP($A776&" Corp","CRNCY")) | H776: =IF($A776="","",IFERROR(INDEX(SYZ_static!$T$2:$T$806,MATCH($A776,SYZ_static!$A$2:$A$806,0)),_xll.BDP($A776&" Corp","RTG_SP"))) | I776: =IF($A776="","",IFERROR(INDEX(SYZ_static!$S$2:$S$806,MATCH($A776,SYZ_static!$A$2:$A$806,0)),"")) | J776: =IF($A776="","",_xll.BDP($A776&" Corp","PAYMENT_RANK")) | K776: =IF($A776="","",_xll.BDP($A776&" Corp","CPN")) | L776: =IF($A776="","",_xll.BDP($A776&" Corp","MATURITY")) | M776: =IF($A776="","",IFERROR(_xll.BDP($A776&" Corp","MIN_PIECE")/1000,"")) | N776: =IF($A776="","",_xll.BDP($A776&" Corp","PX_LAST")) | O776: =IF($A776="","",_xll.BDP($A776&" Corp","YAS_BOND_YLD","YAS_YLD_FLAG=15")) | P776: =IF($A776="","",_xll.BDP($A776&" Corp","YAS_MOD_DUR")) | Q776: =IF($A776="","",_xll.BDP($A776&" Corp","YAS_OAS_SPRD")) | R776: =IF($A776="","",_xll.BDP($A776&" Corp","YAS_OAS_SPRD","SETTLE_DT",$B$2)) | S776: =IF($A776="","",IF(OR(NOT(ISNUMBER($Q776)),NOT(ISNUMBER($R776))),"",$Q776-$R776)) | T776: =IF($A776="","",_xll.BDP($A776&" Corp","YAS_BOND_YLD","YAS_YLD_FLAG=15","SETTLE_DT",$B$2)) | U776: =IF($A776="","",IF(OR(NOT(ISNUMBER($O776)),NOT(ISNUMBER($T776))),"",$O776-$T776)) | V776: =IF(NOT(ISNUMBER($S776)),"",COUNTIFS($G$7:$G$850,$G776,$S$7:$S$850,">"&$S776)+COUNTIFS($G$7:$G776,$G776,$S$7:$S776,$S776)) | W776: =IF(NOT(ISNUMBER($S776)),"",COUNTIFS($G$7:$G$850,$G776,$S$7:$S$850,"<"&$S776)+COUNTIFS($G$7:$G776,$G776,$S$7:$S776,$S776)) | X776: =IF($V776="","",$G776&"|"&$V776) | Y776: =IF($W776="","",$G776&"|"&$W776)
B777: =IF($A777="","",PROPER(_xll.BDP($A777&" Corp","NAME"))) | C777: =IF($A777="","",IFERROR(INDEX(Company_desc!$B$2:$B$1144,MATCH($A777,Company_desc!$A$2:$A$1144,0)),IFERROR(INDEX(SYZ_static!$Q$2:$Q$806,MATCH($A777,SYZ_static!$A$2:$A$806,0)),""))) | D777: =IF($A777="","",IFERROR(INDEX(SYZ_static!$B$2:$B$806,MATCH($A777,SYZ_static!$A$2:$A$806,0)),"")) | E777: =IF($A777="","",_xll.BDP($A777&" Corp","INDUSTRY_SECTOR")) | F777: =IF($A777="","",PROPER(_xll.BDP($A777&" Corp","COUNTRY_FULL_NAME"))) | G777: =IF($A777="","",_xll.BDP($A777&" Corp","CRNCY")) | H777: =IF($A777="","",IFERROR(INDEX(SYZ_static!$T$2:$T$806,MATCH($A777,SYZ_static!$A$2:$A$806,0)),_xll.BDP($A777&" Corp","RTG_SP"))) | I777: =IF($A777="","",IFERROR(INDEX(SYZ_static!$S$2:$S$806,MATCH($A777,SYZ_static!$A$2:$A$806,0)),"")) | J777: =IF($A777="","",_xll.BDP($A777&" Corp","PAYMENT_RANK")) | K777: =IF($A777="","",_xll.BDP($A777&" Corp","CPN")) | L777: =IF($A777="","",_xll.BDP($A777&" Corp","MATURITY")) | M777: =IF($A777="","",IFERROR(_xll.BDP($A777&" Corp","MIN_PIECE")/1000,"")) | N777: =IF($A777="","",_xll.BDP($A777&" Corp","PX_LAST")) | O777: =IF($A777="","",_xll.BDP($A777&" Corp","YAS_BOND_YLD","YAS_YLD_FLAG=15")) | P777: =IF($A777="","",_xll.BDP($A777&" Corp","YAS_MOD_DUR")) | Q777: =IF($A777="","",_xll.BDP($A777&" Corp","YAS_OAS_SPRD")) | R777: =IF($A777="","",_xll.BDP($A777&" Corp","YAS_OAS_SPRD","SETTLE_DT",$B$2)) | S777: =IF($A777="","",IF(OR(NOT(ISNUMBER($Q777)),NOT(ISNUMBER($R777))),"",$Q777-$R777)) | T777: =IF($A777="","",_xll.BDP($A777&" Corp","YAS_BOND_YLD","YAS_YLD_FLAG=15","SETTLE_DT",$B$2)) | U777: =IF($A777="","",IF(OR(NOT(ISNUMBER($O777)),NOT(ISNUMBER($T777))),"",$O777-$T777)) | V777: =IF(NOT(ISNUMBER($S777)),"",COUNTIFS($G$7:$G$850,$G777,$S$7:$S$850,">"&$S777)+COUNTIFS($G$7:$G777,$G777,$S$7:$S777,$S777)) | W777: =IF(NOT(ISNUMBER($S777)),"",COUNTIFS($G$7:$G$850,$G777,$S$7:$S$850,"<"&$S777)+COUNTIFS($G$7:$G777,$G777,$S$7:$S777,$S777)) | X777: =IF($V777="","",$G777&"|"&$V777) | Y777: =IF($W777="","",$G777&"|"&$W777)
B778: =IF($A778="","",PROPER(_xll.BDP($A778&" Corp","NAME"))) | C778: =IF($A778="","",IFERROR(INDEX(Company_desc!$B$2:$B$1144,MATCH($A778,Company_desc!$A$2:$A$1144,0)),IFERROR(INDEX(SYZ_static!$Q$2:$Q$806,MATCH($A778,SYZ_static!$A$2:$A$806,0)),""))) | D778: =IF($A778="","",IFERROR(INDEX(SYZ_static!$B$2:$B$806,MATCH($A778,SYZ_static!$A$2:$A$806,0)),"")) | E778: =IF($A778="","",_xll.BDP($A778&" Corp","INDUSTRY_SECTOR")) | F778: =IF($A778="","",PROPER(_xll.BDP($A778&" Corp","COUNTRY_FULL_NAME"))) | G778: =IF($A778="","",_xll.BDP($A778&" Corp","CRNCY")) | H778: =IF($A778="","",IFERROR(INDEX(SYZ_static!$T$2:$T$806,MATCH($A778,SYZ_static!$A$2:$A$806,0)),_xll.BDP($A778&" Corp","RTG_SP"))) | I778: =IF($A778="","",IFERROR(INDEX(SYZ_static!$S$2:$S$806,MATCH($A778,SYZ_static!$A$2:$A$806,0)),"")) | J778: =IF($A778="","",_xll.BDP($A778&" Corp","PAYMENT_RANK")) | K778: =IF($A778="","",_xll.BDP($A778&" Corp","CPN")) | L778: =IF($A778="","",_xll.BDP($A778&" Corp","MATURITY")) | M778: =IF($A778="","",IFERROR(_xll.BDP($A778&" Corp","MIN_PIECE")/1000,"")) | N778: =IF($A778="","",_xll.BDP($A778&" Corp","PX_LAST")) | O778: =IF($A778="","",_xll.BDP($A778&" Corp","YAS_BOND_YLD","YAS_YLD_FLAG=15")) | P778: =IF($A778="","",_xll.BDP($A778&" Corp","YAS_MOD_DUR")) | Q778: =IF($A778="","",_xll.BDP($A778&" Corp","YAS_OAS_SPRD")) | R778: =IF($A778="","",_xll.BDP($A778&" Corp","YAS_OAS_SPRD","SETTLE_DT",$B$2)) | S778: =IF($A778="","",IF(OR(NOT(ISNUMBER($Q778)),NOT(ISNUMBER($R778))),"",$Q778-$R778)) | T778: =IF($A778="","",_xll.BDP($A778&" Corp","YAS_BOND_YLD","YAS_YLD_FLAG=15","SETTLE_DT",$B$2)) | U778: =IF($A778="","",IF(OR(NOT(ISNUMBER($O778)),NOT(ISNUMBER($T778))),"",$O778-$T778)) | V778: =IF(NOT(ISNUMBER($S778)),"",COUNTIFS($G$7:$G$850,$G778,$S$7:$S$850,">"&$S778)+COUNTIFS($G$7:$G778,$G778,$S$7:$S778,$S778)) | W778: =IF(NOT(ISNUMBER($S778)),"",COUNTIFS($G$7:$G$850,$G778,$S$7:$S$850,"<"&$S778)+COUNTIFS($G$7:$G778,$G778,$S$7:$S778,$S778)) | X778: =IF($V778="","",$G778&"|"&$V778) | Y778: =IF($W778="","",$G778&"|"&$W778)
B779: =IF($A779="","",PROPER(_xll.BDP($A779&" Corp","NAME"))) | C779: =IF($A779="","",IFERROR(INDEX(Company_desc!$B$2:$B$1144,MATCH($A779,Company_desc!$A$2:$A$1144,0)),IFERROR(INDEX(SYZ_static!$Q$2:$Q$806,MATCH($A779,SYZ_static!$A$2:$A$806,0)),""))) | D779: =IF($A779="","",IFERROR(INDEX(SYZ_static!$B$2:$B$806,MATCH($A779,SYZ_static!$A$2:$A$806,0)),"")) | E779: =IF($A779="","",_xll.BDP($A779&" Corp","INDUSTRY_SECTOR")) | F779: =IF($A779="","",PROPER(_xll.BDP($A779&" Corp","COUNTRY_FULL_NAME"))) | G779: =IF($A779="","",_xll.BDP($A779&" Corp","CRNCY")) | H779: =IF($A779="","",IFERROR(INDEX(SYZ_static!$T$2:$T$806,MATCH($A779,SYZ_static!$A$2:$A$806,0)),_xll.BDP($A779&" Corp","RTG_SP"))) | I779: =IF($A779="","",IFERROR(INDEX(SYZ_static!$S$2:$S$806,MATCH($A779,SYZ_static!$A$2:$A$806,0)),"")) | J779: =IF($A779="","",_xll.BDP($A779&" Corp","PAYMENT_RANK")) | K779: =IF($A779="","",_xll.BDP($A779&" Corp","CPN")) | L779: =IF($A779="","",_xll.BDP($A779&" Corp","MATURITY")) | M779: =IF($A779="","",IFERROR(_xll.BDP($A779&" Corp","MIN_PIECE")/1000,"")) | N779: =IF($A779="","",_xll.BDP($A779&" Corp","PX_LAST")) | O779: =IF($A779="","",_xll.BDP($A779&" Corp","YAS_BOND_YLD","YAS_YLD_FLAG=15")) | P779: =IF($A779="","",_xll.BDP($A779&" Corp","YAS_MOD_DUR")) | Q779: =IF($A779="","",_xll.BDP($A779&" Corp","YAS_OAS_SPRD")) | R779: =IF($A779="","",_xll.BDP($A779&" Corp","YAS_OAS_SPRD","SETTLE_DT",$B$2)) | S779: =IF($A779="","",IF(OR(NOT(ISNUMBER($Q779)),NOT(ISNUMBER($R779))),"",$Q779-$R779)) | T779: =IF($A779="","",_xll.BDP($A779&" Corp","YAS_BOND_YLD","YAS_YLD_FLAG=15","SETTLE_DT",$B$2)) | U779: =IF($A779="","",IF(OR(NOT(ISNUMBER($O779)),NOT(ISNUMBER($T779))),"",$O779-$T779)) | V779: =IF(NOT(ISNUMBER($S779)),"",COUNTIFS($G$7:$G$850,$G779,$S$7:$S$850,">"&$S779)+COUNTIFS($G$7:$G779,$G779,$S$7:$S779,$S779)) | W779: =IF(NOT(ISNUMBER($S779)),"",COUNTIFS($G$7:$G$850,$G779,$S$7:$S$850,"<"&$S779)+COUNTIFS($G$7:$G779,$G779,$S$7:$S779,$S779)) | X779: =IF($V779="","",$G779&"|"&$V779) | Y779: =IF($W779="","",$G779&"|"&$W779)
B780: =IF($A780="","",PROPER(_xll.BDP($A780&" Corp","NAME"))) | C780: =IF($A780="","",IFERROR(INDEX(Company_desc!$B$2:$B$1144,MATCH($A780,Company_desc!$A$2:$A$1144,0)),IFERROR(INDEX(SYZ_static!$Q$2:$Q$806,MATCH($A780,SYZ_static!$A$2:$A$806,0)),""))) | D780: =IF($A780="","",IFERROR(INDEX(SYZ_static!$B$2:$B$806,MATCH($A780,SYZ_static!$A$2:$A$806,0)),"")) | E780: =IF($A780="","",_xll.BDP($A780&" Corp","INDUSTRY_SECTOR")) | F780: =IF($A780="","",PROPER(_xll.BDP($A780&" Corp","COUNTRY_FULL_NAME"))) | G780: =IF($A780="","",_xll.BDP($A780&" Corp","CRNCY")) | H780: =IF($A780="","",IFERROR(INDEX(SYZ_static!$T$2:$T$806,MATCH($A780,SYZ_static!$A$2:$A$806,0)),_xll.BDP($A780&" Corp","RTG_SP"))) | I780: =IF($A780="","",IFERROR(INDEX(SYZ_static!$S$2:$S$806,MATCH($A780,SYZ_static!$A$2:$A$806,0)),"")) | J780: =IF($A780="","",_xll.BDP($A780&" Corp","PAYMENT_RANK")) | K780: =IF($A780="","",_xll.BDP($A780&" Corp","CPN")) | L780: =IF($A780="","",_xll.BDP($A780&" Corp","MATURITY")) | M780: =IF($A780="","",IFERROR(_xll.BDP($A780&" Corp","MIN_PIECE")/1000,"")) | N780: =IF($A780="","",_xll.BDP($A780&" Corp","PX_LAST")) | O780: =IF($A780="","",_xll.BDP($A780&" Corp","YAS_BOND_YLD","YAS_YLD_FLAG=15")) | P780: =IF($A780="","",_xll.BDP($A780&" Corp","YAS_MOD_DUR")) | Q780: =IF($A780="","",_xll.BDP($A780&" Corp","YAS_OAS_SPRD")) | R780: =IF($A780="","",_xll.BDP($A780&" Corp","YAS_OAS_SPRD","SETTLE_DT",$B$2)) | S780: =IF($A780="","",IF(OR(NOT(ISNUMBER($Q780)),NOT(ISNUMBER($R780))),"",$Q780-$R780)) | T780: =IF($A780="","",_xll.BDP($A780&" Corp","YAS_BOND_YLD","YAS_YLD_FLAG=15","SETTLE_DT",$B$2)) | U780: =IF($A780="","",IF(OR(NOT(ISNUMBER($O780)),NOT(ISNUMBER($T780))),"",$O780-$T780)) | V780: =IF(NOT(ISNUMBER($S780)),"",COUNTIFS($G$7:$G$850,$G780,$S$7:$S$850,">"&$S780)+COUNTIFS($G$7:$G780,$G780,$S$7:$S780,$S780)) | W780: =IF(NOT(ISNUMBER($S780)),"",COUNTIFS($G$7:$G$850,$G780,$S$7:$S$850,"<"&$S780)+COUNTIFS($G$7:$G780,$G780,$S$7:$S780,$S780)) | X780: =IF($V780="","",$G780&"|"&$V780) | Y780: =IF($W780="","",$G780&"|"&$W780)
B781: =IF($A781="","",PROPER(_xll.BDP($A781&" Corp","NAME"))) | C781: =IF($A781="","",IFERROR(INDEX(Company_desc!$B$2:$B$1144,MATCH($A781,Company_desc!$A$2:$A$1144,0)),IFERROR(INDEX(SYZ_static!$Q$2:$Q$806,MATCH($A781,SYZ_static!$A$2:$A$806,0)),""))) | D781: =IF($A781="","",IFERROR(INDEX(SYZ_static!$B$2:$B$806,MATCH($A781,SYZ_static!$A$2:$A$806,0)),"")) | E781: =IF($A781="","",_xll.BDP($A781&" Corp","INDUSTRY_SECTOR")) | F781: =IF($A781="","",PROPER(_xll.BDP($A781&" Corp","COUNTRY_FULL_NAME"))) | G781: =IF($A781="","",_xll.BDP($A781&" Corp","CRNCY")) | H781: =IF($A781="","",IFERROR(INDEX(SYZ_static!$T$2:$T$806,MATCH($A781,SYZ_static!$A$2:$A$806,0)),_xll.BDP($A781&" Corp","RTG_SP"))) | I781: =IF($A781="","",IFERROR(INDEX(SYZ_static!$S$2:$S$806,MATCH($A781,SYZ_static!$A$2:$A$806,0)),"")) | J781: =IF($A781="","",_xll.BDP($A781&" Corp","PAYMENT_RANK")) | K781: =IF($A781="","",_xll.BDP($A781&" Corp","CPN")) | L781: =IF($A781="","",_xll.BDP($A781&" Corp","MATURITY")) | M781: =IF($A781="","",IFERROR(_xll.BDP($A781&" Corp","MIN_PIECE")/1000,"")) | N781: =IF($A781="","",_xll.BDP($A781&" Corp","PX_LAST")) | O781: =IF($A781="","",_xll.BDP($A781&" Corp","YAS_BOND_YLD","YAS_YLD_FLAG=15")) | P781: =IF($A781="","",_xll.BDP($A781&" Corp","YAS_MOD_DUR")) | Q781: =IF($A781="","",_xll.BDP($A781&" Corp","YAS_OAS_SPRD")) | R781: =IF($A781="","",_xll.BDP($A781&" Corp","YAS_OAS_SPRD","SETTLE_DT",$B$2)) | S781: =IF($A781="","",IF(OR(NOT(ISNUMBER($Q781)),NOT(ISNUMBER($R781))),"",$Q781-$R781)) | T781: =IF($A781="","",_xll.BDP($A781&" Corp","YAS_BOND_YLD","YAS_YLD_FLAG=15","SETTLE_DT",$B$2)) | U781: =IF($A781="","",IF(OR(NOT(ISNUMBER($O781)),NOT(ISNUMBER($T781))),"",$O781-$T781)) | V781: =IF(NOT(ISNUMBER($S781)),"",COUNTIFS($G$7:$G$850,$G781,$S$7:$S$850,">"&$S781)+COUNTIFS($G$7:$G781,$G781,$S$7:$S781,$S781)) | W781: =IF(NOT(ISNUMBER($S781)),"",COUNTIFS($G$7:$G$850,$G781,$S$7:$S$850,"<"&$S781)+COUNTIFS($G$7:$G781,$G781,$S$7:$S781,$S781)) | X781: =IF($V781="","",$G781&"|"&$V781) | Y781: =IF($W781="","",$G781&"|"&$W781)
... B850: =IF($A850="","",PROPER(_xll.BDP($A850&" Corp","NAME"))) | C850: =IF($A850="","",IFERROR(INDEX(Company_desc!$B$2:$B$1144,MATCH($A850,Company_desc!$A$2:$A$1144,0)),IFERROR(INDEX(SYZ_static!$Q$2:$Q$806,MATCH($A850,SYZ_static!$A$2:$A$806,0)),""))) | D850: =IF($A850="","",IFERROR(INDEX(SYZ_static!$B$2:$B$806,MATCH($A850,SYZ_static!$A$2:$A$806,0)),"")) | E850: =IF($A850="","",_xll.BDP($A850&" Corp","INDUSTRY_SECTOR")) | F850: =IF($A850="","",PROPER(_xll.BDP($A850&" Corp","COUNTRY_FULL_NAME"))) | G850: =IF($A850="","",_xll.BDP($A850&" Corp","CRNCY")) | H850: =IF($A850="","",IFERROR(INDEX(SYZ_static!$T$2:$T$806,MATCH($A850,SYZ_static!$A$2:$A$806,0)),_xll.BDP($A850&" Corp","RTG_SP"))) | I850: =IF($A850="","",IFERROR(INDEX(SYZ_static!$S$2:$S$806,MATCH($A850,SYZ_static!$A$2:$A$806,0)),"")) | J850: =IF($A850="","",_xll.BDP($A850&" Corp","PAYMENT_RANK")) | K850: =IF($A850="","",_xll.BDP($A850&" Corp","CPN")) | L850: =IF($A850="","",_xll.BDP($A850&" Corp","MATURITY")) | M850: =IF($A850="","",IFERROR(_xll.BDP($A850&" Corp","MIN_PIECE")/1000,"")) | N850: =IF($A850="","",_xll.BDP($A850&" Corp","PX_LAST")) | O850: =IF($A850="","",_xll.BDP($A850&" Corp","YAS_BOND_YLD","YAS_YLD_FLAG=15")) | P850: =IF($A850="","",_xll.BDP($A850&" Corp","YAS_MOD_DUR")) | Q850: =IF($A850="","",_xll.BDP($A850&" Corp","YAS_OAS_SPRD")) | R850: =IF($A850="","",_xll.BDP($A850&" Corp","YAS_OAS_SPRD","SETTLE_DT",$B$2)) | S850: =IF($A850="","",IF(OR(NOT(ISNUMBER($Q850)),NOT(ISNUMBER($R850))),"",$Q850-$R850)) | T850: =IF($A850="","",_xll.BDP($A850&" Corp","YAS_BOND_YLD","YAS_YLD_FLAG=15","SETTLE_DT",$B$2)) | U850: =IF($A850="","",IF(OR(NOT(ISNUMBER($O850)),NOT(ISNUMBER($T850))),"",$O850-$T850)) | V850: =IF(NOT(ISNUMBER($S850)),"",COUNTIFS($G$7:$G$850,$G850,$S$7:$S$850,">"&$S850)+COUNTIFS($G$7:$G850,$G850,$S$7:$S850,$S850)) | W850: =IF(NOT(ISNUMBER($S850)),"",COUNTIFS($G$7:$G$850,$G850,$S$7:$S$850,"<"&$S850)+COUNTIFS($G$7:$G850,$G850,$S$7:$S850,$S850)) | X850: =IF($V850="","",$G850&"|"&$V850) | Y850: =IF($W850="","",$G850&"|"&$W850)

Sheet Top & Bottom
A1: Biggest spread movers since 14.07.2026
A2: ='Spread Monitor'!$B$2
A3: Ranked within each currency. Live formulas - they follow the Spread Monitor sheet automatically.
A5: USD - Top 10 that widened the most since 14.07.2026
A6: ISIN | B6: Company | C6: Company description | D6: Sector | E6: Ccy | F6: Rating | G6: Maturity | H6: YTW (%) | I6: Spread today (bp) | J6: Spread on anchor (bp) | K6: Spread change (bp)
A7: =IFERROR(INDEX('Spread Monitor'!$A$7:$A$850,MATCH("USD|1",'Spread Monitor'!$X$7:$X$850,0)),"") | B7: =IFERROR(INDEX('Spread Monitor'!$B$7:$B$850,MATCH("USD|1",'Spread Monitor'!$X$7:$X$850,0)),"") | C7: =IFERROR(INDEX('Spread Monitor'!$C$7:$C$850,MATCH("USD|1",'Spread Monitor'!$X$7:$X$850,0)),"") | D7: =IFERROR(INDEX('Spread Monitor'!$E$7:$E$850,MATCH("USD|1",'Spread Monitor'!$X$7:$X$850,0)),"") | E7: =IFERROR(INDEX('Spread Monitor'!$G$7:$G$850,MATCH("USD|1",'Spread Monitor'!$X$7:$X$850,0)),"") | F7: =IFERROR(INDEX('Spread Monitor'!$H$7:$H$850,MATCH("USD|1",'Spread Monitor'!$X$7:$X$850,0)),"") | G7: =IFERROR(INDEX('Spread Monitor'!$L$7:$L$850,MATCH("USD|1",'Spread Monitor'!$X$7:$X$850,0)),"") | H7: =IFERROR(INDEX('Spread Monitor'!$O$7:$O$850,MATCH("USD|1",'Spread Monitor'!$X$7:$X$850,0)),"") | I7: =IFERROR(INDEX('Spread Monitor'!$Q$7:$Q$850,MATCH("USD|1",'Spread Monitor'!$X$7:$X$850,0)),"") | J7: =IFERROR(INDEX('Spread Monitor'!$R$7:$R$850,MATCH("USD|1",'Spread Monitor'!$X$7:$X$850,0)),"") | K7: =IFERROR(INDEX('Spread Monitor'!$S$7:$S$850,MATCH("USD|1",'Spread Monitor'!$X$7:$X$850,0)),"")
A8: =IFERROR(INDEX('Spread Monitor'!$A$7:$A$850,MATCH("USD|2",'Spread Monitor'!$X$7:$X$850,0)),"") | B8: =IFERROR(INDEX('Spread Monitor'!$B$7:$B$850,MATCH("USD|2",'Spread Monitor'!$X$7:$X$850,0)),"") | C8: =IFERROR(INDEX('Spread Monitor'!$C$7:$C$850,MATCH("USD|2",'Spread Monitor'!$X$7:$X$850,0)),"") | D8: =IFERROR(INDEX('Spread Monitor'!$E$7:$E$850,MATCH("USD|2",'Spread Monitor'!$X$7:$X$850,0)),"") | E8: =IFERROR(INDEX('Spread Monitor'!$G$7:$G$850,MATCH("USD|2",'Spread Monitor'!$X$7:$X$850,0)),"") | F8: =IFERROR(INDEX('Spread Monitor'!$H$7:$H$850,MATCH("USD|2",'Spread Monitor'!$X$7:$X$850,0)),"") | G8: =IFERROR(INDEX('Spread Monitor'!$L$7:$L$850,MATCH("USD|2",'Spread Monitor'!$X$7:$X$850,0)),"") | H8: =IFERROR(INDEX('Spread Monitor'!$O$7:$O$850,MATCH("USD|2",'Spread Monitor'!$X$7:$X$850,0)),"") | I8: =IFERROR(INDEX('Spread Monitor'!$Q$7:$Q$850,MATCH("USD|2",'Spread Monitor'!$X$7:$X$850,0)),"") | J8: =IFERROR(INDEX('Spread Monitor'!$R$7:$R$850,MATCH("USD|2",'Spread Monitor'!$X$7:$X$850,0)),"") | K8: =IFERROR(INDEX('Spread Monitor'!$S$7:$S$850,MATCH("USD|2",'Spread Monitor'!$X$7:$X$850,0)),"")
A9: =IFERROR(INDEX('Spread Monitor'!$A$7:$A$850,MATCH("USD|3",'Spread Monitor'!$X$7:$X$850,0)),"") | B9: =IFERROR(INDEX('Spread Monitor'!$B$7:$B$850,MATCH("USD|3",'Spread Monitor'!$X$7:$X$850,0)),"") | C9: =IFERROR(INDEX('Spread Monitor'!$C$7:$C$850,MATCH("USD|3",'Spread Monitor'!$X$7:$X$850,0)),"") | D9: =IFERROR(INDEX('Spread Monitor'!$E$7:$E$850,MATCH("USD|3",'Spread Monitor'!$X$7:$X$850,0)),"") | E9: =IFERROR(INDEX('Spread Monitor'!$G$7:$G$850,MATCH("USD|3",'Spread Monitor'!$X$7:$X$850,0)),"") | F9: =IFERROR(INDEX('Spread Monitor'!$H$7:$H$850,MATCH("USD|3",'Spread Monitor'!$X$7:$X$850,0)),"") | G9: =IFERROR(INDEX('Spread Monitor'!$L$7:$L$850,MATCH("USD|3",'Spread Monitor'!$X$7:$X$850,0)),"") | H9: =IFERROR(INDEX('Spread Monitor'!$O$7:$O$850,MATCH("USD|3",'Spread Monitor'!$X$7:$X$850,0)),"") | I9: =IFERROR(INDEX('Spread Monitor'!$Q$7:$Q$850,MATCH("USD|3",'Spread Monitor'!$X$7:$X$850,0)),"") | J9: =IFERROR(INDEX('Spread Monitor'!$R$7:$R$850,MATCH("USD|3",'Spread Monitor'!$X$7:$X$850,0)),"") | K9: =IFERROR(INDEX('Spread Monitor'!$S$7:$S$850,MATCH("USD|3",'Spread Monitor'!$X$7:$X$850,0)),"")
A10: =IFERROR(INDEX('Spread Monitor'!$A$7:$A$850,MATCH("USD|4",'Spread Monitor'!$X$7:$X$850,0)),"") | B10: =IFERROR(INDEX('Spread Monitor'!$B$7:$B$850,MATCH("USD|4",'Spread Monitor'!$X$7:$X$850,0)),"") | C10: =IFERROR(INDEX('Spread Monitor'!$C$7:$C$850,MATCH("USD|4",'Spread Monitor'!$X$7:$X$850,0)),"") | D10: =IFERROR(INDEX('Spread Monitor'!$E$7:$E$850,MATCH("USD|4",'Spread Monitor'!$X$7:$X$850,0)),"") | E10: =IFERROR(INDEX('Spread Monitor'!$G$7:$G$850,MATCH("USD|4",'Spread Monitor'!$X$7:$X$850,0)),"") | F10: =IFERROR(INDEX('Spread Monitor'!$H$7:$H$850,MATCH("USD|4",'Spread Monitor'!$X$7:$X$850,0)),"") | G10: =IFERROR(INDEX('Spread Monitor'!$L$7:$L$850,MATCH("USD|4",'Spread Monitor'!$X$7:$X$850,0)),"") | H10: =IFERROR(INDEX('Spread Monitor'!$O$7:$O$850,MATCH("USD|4",'Spread Monitor'!$X$7:$X$850,0)),"") | I10: =IFERROR(INDEX('Spread Monitor'!$Q$7:$Q$850,MATCH("USD|4",'Spread Monitor'!$X$7:$X$850,0)),"") | J10: =IFERROR(INDEX('Spread Monitor'!$R$7:$R$850,MATCH("USD|4",'Spread Monitor'!$X$7:$X$850,0)),"") | K10: =IFERROR(INDEX('Spread Monitor'!$S$7:$S$850,MATCH("USD|4",'Spread Monitor'!$X$7:$X$850,0)),"")
A11: =IFERROR(INDEX('Spread Monitor'!$A$7:$A$850,MATCH("USD|5",'Spread Monitor'!$X$7:$X$850,0)),"") | B11: =IFERROR(INDEX('Spread Monitor'!$B$7:$B$850,MATCH("USD|5",'Spread Monitor'!$X$7:$X$850,0)),"") | C11: =IFERROR(INDEX('Spread Monitor'!$C$7:$C$850,MATCH("USD|5",'Spread Monitor'!$X$7:$X$850,0)),"") | D11: =IFERROR(INDEX('Spread Monitor'!$E$7:$E$850,MATCH("USD|5",'Spread Monitor'!$X$7:$X$850,0)),"") | E11: =IFERROR(INDEX('Spread Monitor'!$G$7:$G$850,MATCH("USD|5",'Spread Monitor'!$X$7:$X$850,0)),"") | F11: =IFERROR(INDEX('Spread Monitor'!$H$7:$H$850,MATCH("USD|5",'Spread Monitor'!$X$7:$X$850,0)),"") | G11: =IFERROR(INDEX('Spread Monitor'!$L$7:$L$850,MATCH("USD|5",'Spread Monitor'!$X$7:$X$850,0)),"") | H11: =IFERROR(INDEX('Spread Monitor'!$O$7:$O$850,MATCH("USD|5",'Spread Monitor'!$X$7:$X$850,0)),"") | I11: =IFERROR(INDEX('Spread Monitor'!$Q$7:$Q$850,MATCH("USD|5",'Spread Monitor'!$X$7:$X$850,0)),"") | J11: =IFERROR(INDEX('Spread Monitor'!$R$7:$R$850,MATCH("USD|5",'Spread Monitor'!$X$7:$X$850,0)),"") | K11: =IFERROR(INDEX('Spread Monitor'!$S$7:$S$850,MATCH("USD|5",'Spread Monitor'!$X$7:$X$850,0)),"")
A12: =IFERROR(INDEX('Spread Monitor'!$A$7:$A$850,MATCH("USD|6",'Spread Monitor'!$X$7:$X$850,0)),"") | B12: =IFERROR(INDEX('Spread Monitor'!$B$7:$B$850,MATCH("USD|6",'Spread Monitor'!$X$7:$X$850,0)),"") | C12: =IFERROR(INDEX('Spread Monitor'!$C$7:$C$850,MATCH("USD|6",'Spread Monitor'!$X$7:$X$850,0)),"") | D12: =IFERROR(INDEX('Spread Monitor'!$E$7:$E$850,MATCH("USD|6",'Spread Monitor'!$X$7:$X$850,0)),"") | E12: =IFERROR(INDEX('Spread Monitor'!$G$7:$G$850,MATCH("USD|6",'Spread Monitor'!$X$7:$X$850,0)),"") | F12: =IFERROR(INDEX('Spread Monitor'!$H$7:$H$850,MATCH("USD|6",'Spread Monitor'!$X$7:$X$850,0)),"") | G12: =IFERROR(INDEX('Spread Monitor'!$L$7:$L$850,MATCH("USD|6",'Spread Monitor'!$X$7:$X$850,0)),"") | H12: =IFERROR(INDEX('Spread Monitor'!$O$7:$O$850,MATCH("USD|6",'Spread Monitor'!$X$7:$X$850,0)),"") | I12: =IFERROR(INDEX('Spread Monitor'!$Q$7:$Q$850,MATCH("USD|6",'Spread Monitor'!$X$7:$X$850,0)),"") | J12: =IFERROR(INDEX('Spread Monitor'!$R$7:$R$850,MATCH("USD|6",'Spread Monitor'!$X$7:$X$850,0)),"") | K12: =IFERROR(INDEX('Spread Monitor'!$S$7:$S$850,MATCH("USD|6",'Spread Monitor'!$X$7:$X$850,0)),"")
